Workbook

Sheet Overview
A1: AlikeAudience Data Test — Task 1 Analysis
A2: Source: alikeaudience_data_test.csv (100,000 events, Dec 2022). Enriched by pipeline.py (geo, device, IP, time features).
A4: Key metrics
A5: Total events / unique users | B5: =Aggregates!B1 -> 100000
A6: Date range | B6: Dec 1 – Dec 31, 2022 (UTC)
A7: Countries covered | B7: =COUNTA(Aggregates!A5:A16) -> 12
A8: Top country | B8: =Aggregates!A5 -> Japan
A9: Top country share | B9: =Aggregates!B5/Aggregates!B1 -> 0.30244
A10: Android share | B10: =Aggregates!B21/Aggregates!B1 -> 0.9441
A11: In-app WebView share | B11: =(Aggregates!B43+Aggregates!B45)/Aggregates!B1 -> 0.91577
A12: Missing user agents | B12: =Aggregates!B2 -> 1909
A13: Non-routable IPs (DQ flag) | B13: =Aggregates!B3 -> 4192
A15: Key findings
A16: 1. Source column 'lat_long' is actually LONGITUDE LATITUDE — corrected in the enriched data.
A17: 2. Volume anomaly: Dec 6 spikes to ~6x baseline (12,987 vs ~2,100/day); second ramp Dec 28–31.
A18: 3. Traffic is 96% Android and 92% in-app WebView — this is SDK/in-app traffic, not browser traffic.
A19: 4. Data shows synthetic-generation signals: 4,192 non-routable IPs; only 13.2% of IPv6 in 2000::/3.
A20: 5. Geography is entirely East/SE Asia; Japan + Indonesia = 60% of events.
A22: Note: aggregate tables on the 'Aggregates' sheet are computed by pipeline.py over the full 100,000 rows; percentages and KPIs above are live formulas over those tables. 'Sample Data' holds the first 2,000 enriched rows; the full file is enriched_data.csv.

Sheet Aggregates
A1: TOTAL_EVENTS | B1: 100000 | D1: Source: computed by pipeline.py over all 100,000 rows of alikeaudience_data_test.csv.
A2: MISSING_UA | B2: 1909
A3: Country (top 12) | B3: 4192
A4: Country | B4: Events | C4: % of total
A5: Japan | B5: 30244 | C5: =B5/$B$1 -> 0.30244
A6: Indonesia | B6: 29994 | C6: =B6/$B$1 -> 0.29994
A7: South Korea | B7: 9845 | C7: =B7/$B$1 -> 0.09845
A8: Vietnam | B8: 7235 | C8: =B8/$B$1 -> 0.07235
A9: Thailand | B9: 6645 | C9: =B9/$B$1 -> 0.06645
A10: Philippines | B10: 5058 | C10: =B10/$B$1 -> 0.05058
A11: Taiwan | B11: 5055 | C11: =B11/$B$1 -> 0.05055
A12: Malaysia | B12: 3874 | C12: =B12/$B$1 -> 0.03874
A13: Singapore | B13: 1262 | C13: =B13/$B$1 -> 0.01262
A14: Hong Kong | B14: 223 | C14: =B14/$B$1 -> 0.00223
A15: Laos | B15: 221 | C15: =B15/$B$1 -> 0.00221
A16: Cambodia | B16: 118 | C16: =B16/$B$1 -> 0.00118
A19: Operating system
A20: OS | B20: Events | C20: % of total
A21: Android | B21: 94410 | C21: =B21/$B$1 -> 0.9441
A22: iOS | B22: 3664 | C22: =B22/$B$1 -> 0.03664
A23: (unknown / missing UA) | B23: 1911 | C23: =B23/$B$1 -> 0.01911
A24: macOS | B24: 15 | C24: =B24/$B$1 -> 0.00015
A27: Device brand (top 10)
A28: Brand | B28: Events | C28: % of total
A29: Samsung | B29: 55998 | C29: =B29/$B$1 -> 0.55998
A30: Motorola | B30: 13770 | C30: =B30/$B$1 -> 0.1377
A31: (other/unknown) | B31: 9557 | C31: =B31/$B$1 -> 0.09557
A32: Google | B32: 3959 | C32: =B32/$B$1 -> 0.03959
A33: Apple | B33: 3679 | C33: =B33/$B$1 -> 0.03679
A34: LG | B34: 3337 | C34: =B34/$B$1 -> 0.03337
A35: OnePlus | B35: 2169 | C35: =B35/$B$1 -> 0.02169
A36: Xiaomi | B36: 1985 | C36: =B36/$B$1 -> 0.01985
A37: T-Mobile | B37: 1196 | C37: =B37/$B$1 -> 0.01196
A38: TCL | B38: 544 | C38: =B38/$B$1 -> 0.00544
A41: Browser / WebView
A42: Browser | B42: Events | C42: % of total
A43: Android WebView | B43: 87934 | C43: =B43/$B$1 -> 0.87934
A44: (unknown / missing UA) | B44: 8369 | C44: =B44/$B$1 -> 0.08369
A45: iOS WebView | B45: 3643 | C45: =B45/$B$1 -> 0.03643
A46: Chrome | B46: 29 | C46: =B46/$B$1 -> 0.00029
...

Sheet Time
A1: Daily event volume — December 2022 | E1: Events by local hour (longitude-approximated)
A2: Date | B2: Events | E2: Local hour | F2: Events
A3: 2022-12-01 | B3: 2235 | E3: 0 | F3: 2197
A4: 2022-12-02 | B4: 3359 | E4: 1 | F4: 1802
A5: 2022-12-03 | B5: 2881 | E5: 2 | F5: 1524
A6: 2022-12-04 | B6: 3542 | E6: 3 | F6: 1411
A7: 2022-12-05 | B7: 3532 | E7: 4 | F7: 1423
A8: 2022-12-06 | B8: 12987 | E8: 5 | F8: 1929
A9: 2022-12-07 | B9: 8628 | E9: 6 | F9: 2839
A10: 2022-12-08 | B10: 4543 | E10: 7 | F10: 3409
A11: 2022-12-09 | B11: 6558 | E11: 8 | F11: 3652
A12: 2022-12-10 | B12: 2220 | E12: 9 | F12: 4198
A13: 2022-12-11 | B13: 2389 | E13: 10 | F13: 4980
A14: 2022-12-12 | B14: 2235 | E14: 11 | F14: 5377
... A26: 2022-12-24 | B26: 2019 | E26: 23 | F26: 2856
A27: 2022-12-25 | B27: 2097
A28: 2022-12-26 | B28: 1925
A29: 2022-12-27 | B29: 2114
A30: 2022-12-28 | B30: 2838
A31: 2022-12-29 | B31: 3153
A32: 2022-12-30 | B32: 4213
A33: 2022-12-31 | B33: 3971
A34: Total | B34: =SUM(B3:B33) -> 100000

Sheet Charts
A1: Distribution charts (data on 'Aggregates')

Sheet Sample Data
A1: user_id | B1: timestamp | C1: latitude | D1: longitude | E1: country | F1: nearest_city | G1: geo_confidence | H1: local_hour | I1: dow | J1: is_weekend | K1: ip_version | L1: ip_routable | M1: os_family | N1: os_version | O1: device_brand | P1: device_model | Q1: form_factor | R1: browser | S1: is_webview
A2: c975b38c-3520-4f2c-90d3-d2018f296673 | B2: 2022-12-18T01:14:56.000Z | C2: 35.88585 | D2: 139.96747 | E2: Japan | F2: Tokyo | G2: high | H2: 10 | I2: Sunday | J2: =TRUE() -> TRUE | K2: 6 | L2: =TRUE() -> TRUE | M2: iOS | N2: 15.6 | O2: Apple | P2: iPhone | Q2: phone | R2: iOS WebView | S2: =TRUE() -> TRUE
A3: e9ecf555-f2d2-4b57-b466-01918ee46f2d | B3: 2022-12-03T21:37:55.000Z | C3: 4.9872 | D3: 115.9241 | E3: Brunei | F3: Bandar Seri Begawan | G3: medium | H3: 5 | I3: Saturday | J3: =TRUE() -> TRUE | K3: 6 | L3: =TRUE() -> TRUE | M3: Android | N3: 12 | O3: LG | P3: LM-G900 | Q3: phone | R3: Android WebView | S3: =TRUE() -> TRUE
A4: 16ff6ea2-fad4-4395-bcb6-c3c407de6f1a | B4: 2022-12-07T01:07:23.000Z | C4: -6.0064116 | D4: 106.05228 | E4: Indonesia | F4: Tangerang | G4: high | H4: 8 | I4: Wednesday | J4: =FALSE() -> FALSE | K4: 6 | L4: =TRUE() -> TRUE | M4: Android | N4: 10 | O4: Nokia | P4: Nokia C5 Endi | Q4: phone | R4: Android WebView | S4: =TRUE() -> TRUE
A5: 8151fee2-9eb6-4e22-896f-dea112ec4aae | B5: 2022-12-06T03:36:24.000Z | C5: 14.620271 | D5: 121.05059 | E5: Philippines | F5: Quezon City | G5: high | H5: 11 | I5: Tuesday | J5: =FALSE() -> FALSE | K5: 4 | L5: =TRUE() -> TRUE | M5: Android | N5: 11 | O5: Motorola | P5: moto g stylus (2021 | Q5: phone | R5: Android WebView | S5: =TRUE() -> TRUE
A6: 830a7900-b021-44de-aeb6-1daedf1e9d3f | B6: 2022-12-06T03:14:33.000Z | C6: -6.26 | D6: 106.81 | E6: Indonesia | F6: Jakarta | G6: high | H6: 10 | I6: Tuesday | J6: =FALSE() -> FALSE | K6: 6 | L6: =FALSE() -> FALSE | M6: Android | N6: 10 | O6: Samsung | P6: SM-G960U1 | Q6: phone | R6: Android WebView | S6: =TRUE() -> TRUE
A7: 874a423a-4a25-4f04-bf8a-4ed4dc4e4dbe | B7: 2022-12-03T20:04:53.000Z | C7: 37.186316 | D7: 127.0947 | E7: South Korea | F7: Seoul | G7: high | H7: 4 | I7: Saturday | J7: =TRUE() -> TRUE | K7: 4 | L7: =TRUE() -> TRUE | M7: Android | N7: 12 | O7: Samsung | P7: SM-S136DL | Q7: phone | R7: Android WebView | S7: =TRUE() -> TRUE
A8: 4014c63c-0e3e-4b8f-ae2a-439a4e341e9f | B8: 2022-12-01T08:33:53.000Z | C8: 33.529966 | D8: 130.44087 | E8: Japan | F8: Fukuoka | G8: high | H8: 17 | I8: Thursday | J8: =FALSE() -> FALSE | K8: 4 | L8: =TRUE() -> TRUE | M8: Android | N8: 12 | O8: Motorola | P8: moto g stylus 5G | Q8: phone | R8: Android WebView | S8: =TRUE() -> TRUE
A9: cb49dbdc-e390-4b20-8221-a1852b03e339 | B9: 2022-12-03T02:40:32.000Z | C9: 34.90845 | D9: 136.02075 | E9: Japan | F9: Kyoto | G9: high | H9: 11 | I9: Saturday | J9: =TRUE() -> TRUE | K9: 4 | L9: =TRUE() -> TRUE | M9: Android | N9: 10 | O9: Motorola | P9: moto g stylus | Q9: phone | R9: Android WebView | S9: =TRUE() -> TRUE
A10: be79c991-34c2-451e-aec8-9c6ad3b26adf | B10: 2022-12-31T19:39:40.000Z | C10: 32.832993 | D10: 129.98848 | E10: Japan | F10: Kumamoto | G10: high | H10: 4 | I10: Saturday | J10: =TRUE() -> TRUE | K10: 4 | L10: =TRUE() -> TRUE | M10: Android | N10: 10 | O10: Samsung | P10: SM-G965U | Q10: phone | R10: Android WebView | S10: =TRUE() -> TRUE
A11: 5f9985f5-79b1-462e-a069-ce24d784aa0c | B11: 2022-12-06T01:51:17.000Z | C11: -6.2599792 | D11: 106.45239 | E11: Indonesia | F11: Tangerang | G11: high | H11: 8 | I11: Tuesday | J11: =FALSE() -> FALSE | K11: 4 | L11: =TRUE() -> TRUE | M11: Android | N11: 10.0 | O11: Samsung | P11: SM-N970x | Q11: phone | R11: Android WebView | S11: =TRUE() -> TRUE
A12: ff22f1ae-7e25-4483-9ac4-91f615a1d487 | B12: 2022-12-15T04:40:46.000Z | C12: 15.039403 | D12: 120.65489 | E12: Philippines | F12: Angeles | G12: high | H12: 12 | I12: Thursday | J12: =FALSE() -> FALSE | K12: 4 | L12: =TRUE() -> TRUE | M12: Android | N12: 12 | O12: Motorola | P12: moto g power (2022 | Q12: phone | R12: Android WebView | S12: =TRUE() -> TRUE
A13: c4df96d6-8a8c-45f0-8e69-e8dd09ec4ae9 | B13: 2022-12-01T14:18:08.000Z | C13: 35.002282 | D13: 136.01164 | E13: Japan | F13: Kyoto | G13: high | H13: 23 | I13: Thursday | J13: =FALSE() -> FALSE | K13: 4 | L13: =TRUE() -> TRUE | M13: Android | N13: 12 | O13: Samsung | P13: SM-X200 | Q13: tablet | R13: Android WebView | S13: =TRUE() -> TRUE
A14: f9cf6816-6f70-49b4-9b96-190d720df61a | B14: 2022-12-23T02:52:12.000Z | C14: 36.35846 | D14: 127.30386 | E14: South Korea | F14: Daejeon | G14: high | H14: 10 | I14: Friday | J14: =FALSE() -> FALSE | K14: 4 | L14: =TRUE() -> TRUE | M14: Android | N14: 11 | O14: Samsung | P14: SM-S102DL | Q14: phone | R14: Android WebView | S14: =TRUE() -> TRUE
A15: 79eaa73f-88b0-468d-92b7-016a2526ee27 | B15: 2022-12-21T07:29:49.000Z | C15: 38.31734 | D15: 140.82515 | E15: Japan | F15: Sendai | G15: high | H15: 16 | I15: Wednesday | J15: =FALSE() -> FALSE | K15: 4 | L15: =TRUE() -> TRUE | M15: Android | N15: 11 | P15: SHIELD Android TV | Q15: phone | R15: Android WebView | S15: =TRUE() -> TRUE
A16: 80a4d159-4b46-4587-86dd-009ab71987b5 | B16: 2022-12-02T10:14:23.000Z | C16: 5.21124 | D16: 100.51806 | E16: Malaysia | F16: George Town | G16: high | H16: 17 | I16: Friday | J16: =FALSE() -> FALSE | K16: 6 | L16: =TRUE() -> TRUE | M16: Android | N16: 12 | O16: Samsung | P16: SM-A125U1 | Q16: phone | R16: Android WebView | S16: =TRUE() -> TRUE
A17: 9597a2a3-bd72-44f4-9bc6-1ee928b4b202 | B17: 2022-12-06T02:00:08.000Z | C17: -2.73 | D17: 104.71 | E17: Indonesia | F17: Palembang | G17: high | H17: 9 | I17: Tuesday | J17: =FALSE() -> FALSE | K17: 4 | L17: =TRUE() -> TRUE | M17: Android | N17: 12 | O17: Samsung | P17: SM-A115F | Q17: tablet | S17: =FALSE() -> FALSE
A18: 25b87d12-e478-4ff0-9887-b8c0ddd62fd8 | B18: 2022-12-10T01:02:03.000Z | C18: 32.514157 | D18: 130.59542 | E18: Japan | F18: Kumamoto | G18: high | H18: 10 | I18: Saturday | J18: =TRUE() -> TRUE | K18: 4 | L18: =TRUE() -> TRUE | M18: Android | N18: 11 | O18: Motorola | P18: motorola one 5G ace | Q18: phone | R18: Android WebView | S18: =TRUE() -> TRUE
A19: af8a2ee8-ee2f-4602-9e7b-4db45b168529 | B19: 2022-12-08T22:05:58.000Z | C19: 22.667648 | D19: 120.51638 | E19: Taiwan | F19: Kaohsiung | G19: high | H19: 6 | I19: Thursday | J19: =FALSE() -> FALSE | K19: 6 | L19: =TRUE() -> TRUE | M19: iOS | N19: 16.1 | O19: Apple | P19: iPhone | Q19: phone | R19: iOS WebView | S19: =TRUE() -> TRUE
A20: 33f0ab12-8f30-4284-96f7-52e9bc2153ee | B20: 2022-12-06T11:16:20.000Z | C20: -5.10306 | D20: 119.5329 | E20: Indonesia | F20: Makassar | G20: high | H20: 19 | I20: Tuesday | J20: =FALSE() -> FALSE | K20: 6 | L20: =TRUE() -> TRUE | M20: Android | N20: 11 | O20: Samsung | P20: SM-T727U | Q20: tablet | R20: Android WebView | S20: =TRUE() -> TRUE
A21: ccb4d708-1ee2-4983-afc0-97a09b8250d0 | B21: 2022-12-31T11:46:35.000Z | C21: 8.624603 | D21: 98.814514 | E21: Thailand | F21: Surat Thani | G21: high | H21: 18 | I21: Saturday | J21: =TRUE() -> TRUE | K21: 4 | L21: =TRUE() -> TRUE | M21: Android | N21: 6.0.1 | O21: Samsung | P21: SM-S727VL | Q21: phone | R21: Android WebView | S21: =TRUE() -> TRUE
A22: 42baf84e-445e-4b8d-aaff-76b3d539f51f | B22: 2022-12-07T17:04:22.000Z | C22: -6.238845 | D22: 107.11587 | E22: Indonesia | F22: Bekasi | G22: high | H22: 0 | I22: Wednesday | J22: =FALSE() -> FALSE | K22: 4 | L22: =TRUE() -> TRUE | M22: Android | N22: 11 | O22: Motorola | P22: moto g play (2021 | Q22: phone | R22: Android WebView | S22: =TRUE() -> TRUE
A23: 80a38540-c3e6-46c4-94d8-9d664beccb9a | B23: 2022-12-08T01:34:48.000Z | C23: 35.592602 | D23: 139.33281 | E23: Japan | F23: Tokyo | G23: high | H23: 10 | I23: Thursday | J23: =FALSE() -> FALSE | K23: 6 | L23: =TRUE() -> TRUE | M23: Android | N23: 10 | O23: Samsung | P23: SM-N960U | Q23: phone | R23: Android WebView | S23: =TRUE() -> TRUE
A24: fdefcc25-f13e-477e-bba6-a4eac5a0d55f | B24: 2022-12-06T03:49:56.000Z | C24: -6.6 | D24: 106.81 | E24: Indonesia | F24: Depok | G24: high | H24: 10 | I24: Tuesday | J24: =FALSE() -> FALSE | K24: 6 | L24: =TRUE() -> TRUE | M24: Android | N24: 10 | O24: Samsung | P24: SM-N960U | Q24: phone | R24: Android WebView | S24: =TRUE() -> TRUE
A25: aba97b4f-2289-4e54-8e29-5f871bb177f6 | B25: 2022-12-09T03:48:52.000Z | C25: -7.4618144 | D25: 110.27132 | E25: Indonesia | F25: Yogyakarta | G25: high | H25: 10 | I25: Friday | J25: =FALSE() -> FALSE | K25: 4 | L25: =TRUE() -> TRUE | M25: Android | N25: 10 | O25: Samsung | P25: SM-A750FN | Q25: phone | R25: Android WebView | S25: =TRUE() -> TRUE
A26: 4bae464b-829a-460a-993e-558e25e386ba | B26: 2022-12-06T07:10:44.000Z | C26: -7.01 | D26: 110.44 | E26: Indonesia | F26: Semarang | G26: high | H26: 14 | I26: Tuesday | J26: =FALSE() -> FALSE | K26: 4 | L26: =TRUE() -> TRUE | M26: Android | N26: 10 | O26: Motorola | P26: motorola one action | Q26: phone | R26: Android WebView | S26: =TRUE() -> TRUE
A27: 82831357-18b1-49e4-9114-216a8016cbbf | B27: 2022-12-04T04:14:10.000Z | C27: 10.53999 | D27: 105.41629 | E27: Vietnam | F27: Can Tho | G27: high | H27: 11 | I27: Sunday | J27: =TRUE() -> TRUE | K27: 6 | L27: =TRUE() -> TRUE | M27: Android | N27: 12 | O27: Samsung | P27: SM-A715F | Q27: phone | R27: Android WebView | S27: =TRUE() -> TRUE
A28: 53036164-5118-4645-b570-e7203e7e1b0c | B28: 2022-12-24T15:16:16.000Z | C28: 13.695084 | D28: 100.65299 | E28: Thailand | F28: Bangkok | G28: high | H28: 22 | I28: Saturday | J28: =TRUE() -> TRUE | K28: 6 | L28: =TRUE() -> TRUE | M28: Android | N28: 13 | O28: Samsung | P28: SM-A536V | Q28: phone | R28: Android WebView | S28: =TRUE() -> TRUE
A29: c143d0d2-6472-45c7-a5c5-16836e166c0e | B29: 2022-12-03T12:54:49.000Z | C29: 1.44887 | D29: 103.78687 | E29: Malaysia | F29: Johor Bahru | G29: high | H29: 19 | I29: Saturday | J29: =TRUE() -> TRUE | K29: 4 | L29: =TRUE() -> TRUE | M29: Android | N29: 12 | O29: Samsung | P29: SM-G970U | Q29: phone | R29: Android WebView | S29: =TRUE() -> TRUE
A30: 1f1f0044-953c-4934-86c3-7308bc44af4a | B30: 2022-12-24T10:49:41.000Z | C30: 13.73058 | D30: 100.45112 | E30: Thailand | F30: Bangkok | G30: high | H30: 17 | I30: Saturday | J30: =TRUE() -> TRUE | K30: 6 | L30: =TRUE() -> TRUE | M30: Android | N30: 11 | O30: Motorola | P30: moto g stylus (2022 | Q30: phone | R30: Android WebView | S30: =TRUE() -> TRUE
A31: 072b60cd-2c4a-491f-81d0-14a354e083c9 | B31: 2022-12-07T20:56:57.000Z | C31: -6.18 | D31: 106.83 | E31: Indonesia | F31: Jakarta | G31: high | H31: 3 | I31: Wednesday | J31: =FALSE() -> FALSE | K31: 6 | L31: =TRUE() -> TRUE | M31: Android | N31: 13 | O31: Samsung | P31: SM-G986U | Q31: phone | R31: Android WebView | S31: =TRUE() -> TRUE
A32: 3f761322-d525-4f0c-825a-0ae5ece2ac4f | B32: 2022-12-08T02:17:09.000Z | C32: 35.573482 | D32: 139.59973 | E32: Japan | F32: Tokyo | G32: high | H32: 11 | I32: Thursday | J32: =FALSE() -> FALSE | K32: 4 | L32: =TRUE() -> TRUE | M32: Android | N32: 11 | O32: Motorola | P32: moto g power (2021 | Q32: phone | R32: Android WebView | S32: =TRUE() -> TRUE
A33: ac416129-e00b-46c2-8771-f4d179f86ee0 | B33: 2022-12-19T17:18:17.000Z | C33: 34.75362 | D33: 135.33804 | E33: Japan | F33: Kobe | G33: high | H33: 2 | I33: Monday | J33: =FALSE() -> FALSE | K33: 6 | L33: =TRUE() -> TRUE | M33: Android | N33: 13 | O33: Samsung | P33: SM-S908U1 | Q33: phone | R33: Android WebView | S33: =TRUE() -> TRUE
A34: 8236f060-db9a-47a0-9b3d-1558234dd106 | B34: 2022-12-29T03:43:33.000Z | C34: 12.692835 | D34: 108.06519 | E34: Vietnam | F34: Buon Ma Thuot | G34: high | H34: 10 | I34: Thursday | J34: =FALSE() -> FALSE | K34: 6 | L34: =TRUE() -> TRUE | M34: Android | N34: 9 | O34: Xiaomi | P34: Redmi Note 8 MIUI/V11.0.12.0.PCOMIXM | Q34: tablet | S34: =FALSE() -> FALSE
A35: f34fcf85-644e-4d4f-8d7d-05c82817c87d | B35: 2022-12-01T12:18:39.000Z | C35: 34.297925 | D35: 134.10006 | E35: Japan | F35: Okayama | G35: high | H35: 21 | I35: Thursday | J35: =FALSE() -> FALSE | K35: 4 | L35: =TRUE() -> TRUE | M35: Android | N35: 8.1.0 | O35: LG | P35: LM-Q710(FGN | Q35: phone | R35: Android WebView | S35: =TRUE() -> TRUE
A36: aa852a01-3440-457d-859d-6560286a56a9 | B36: 2022-12-17T03:34:45.000Z | C36: 13.83477 | D36: 100.64961 | E36: Thailand | F36: Bangkok | G36: high | H36: 10 | I36: Saturday | J36: =TRUE() -> TRUE | K36: 4 | L36: =TRUE() -> TRUE | M36: Android | N36: 11 | O36: Infinix | P36: Infinix X688B | Q36: phone | R36: Android WebView | S36: =TRUE() -> TRUE
A37: b139f7d2-15ab-4286-8815-610aaccdf160 | B37: 2022-12-16T08:22:29.000Z | C37: -7.637132 | D37: 111.27954 | E37: Indonesia | F37: Surakarta | G37: high | H37: 15 | I37: Friday | J37: =FALSE() -> FALSE | K37: 4 | L37: =TRUE() -> TRUE | M37: Android | N37: 12 | O37: Samsung | P37: SM-G975U | Q37: phone | R37: Android WebView | S37: =TRUE() -> TRUE
A38: 63e1221c-3cb3-454f-8ece-7f9ca5ce7a64 | B38: 2022-12-06T07:23:57.000Z | C38: -7.847499 | D38: 110.36623 | E38: Indonesia | F38: Yogyakarta | G38: high | H38: 14 | I38: Tuesday | J38: =FALSE() -> FALSE | K38: 4 | L38: =TRUE() -> TRUE | M38: Android | N38: 13 | O38: Samsung | P38: SM-G998U | Q38: phone | R38: Android WebView | S38: =TRUE() -> TRUE
A39: 8221286d-7b06-4907-b5e7-b2c1c077d769 | B39: 2022-12-07T05:40:09.000Z | C39: 43.008161 | D39: 141.47316 | E39: Japan | F39: Sapporo | G39: high | H39: 14 | I39: Wednesday | J39: =FALSE() -> FALSE | K39: 6 | L39: =TRUE() -> TRUE | M39: Android | N39: 10 | O39: Samsung | P39: SM-G965U | Q39: phone | R39: Android WebView | S39: =TRUE() -> TRUE
A40: d0c3eaa5-9ce9-4ff0-b44c-b2b4e36f47fa | B40: 2022-12-09T03:00:37.000Z | C40: 35.748008 | D40: 139.68476 | E40: Japan | F40: Tokyo | G40: high | H40: 12 | I40: Friday | J40: =FALSE() -> FALSE | K40: 4 | L40: =TRUE() -> TRUE | M40: Android | N40: 12 | O40: Samsung | P40: SM-N986U | Q40: phone | R40: Android WebView | S40: =TRUE() -> TRUE
...
